<?xml version="1.0"?>
<robot name="minimal_robot">

  <!-- ================= BASE ================= -->
  <link name="base_link">
    <inertial>
      <mass value="1.0"/>
      <origin xyz="0 0 0"/>
      <inertia ixx="0.01" ixy="0.0" ixz="0.0"
               iyy="0.01" iyz="0.0"
               izz="0.01"/>
    </inertial>

    <collision>
      <origin xyz="0 0 0"/>
      <geometry>
        <box size="0.2 0.15 0.05"/>
      </geometry>
    </collision>

    <visual>
      <origin xyz="0 0 0"/>
      <geometry>
        <box size="0.2 0.15 0.05"/>
      </geometry>
      <material name="blue">
        <color rgba="0 0 1 1"/>
      </material>
    </visual>
  </link>

  <!-- ================= LEFT WHEEL ================= -->
  <link name="wheel_left_link">
    <inertial>
      <mass value="0.1"/>
      <origin xyz="0 0 0"/>
      <inertia ixx="0.0001" ixy="0.0" ixz="0.0"
               iyy="0.0001" iyz="0.0"
               izz="0.0001"/>
    </inertial>

    <collision>
      <origin xyz="0 0 0"/>
      <geometry>
        <cylinder radius="0.03" length="0.02"/>
      </geometry>
    </collision>

    <visual>
      <origin xyz="0 0 0"/>
      <geometry>
        <cylinder radius="0.03" length="0.02"/>
      </geometry>
      <material name="green">
        <color rgba="0 1 0 1"/>
      </material>
    </visual>
  </link>

  <joint name="wheel_left_joint" type="continuous">
    <parent link="base_link"/>
    <child link="wheel_left_link"/>
    <origin xyz="0 0.075 0"/>
    <axis xyz="0 1 0"/>
  </joint>

  <!-- ================= RIGHT WHEEL ================= -->
  <link name="wheel_right_link">
    <inertial>
      <mass value="0.1"/>
      <origin xyz="0 0 0"/>
      <inertia ixx="0.0001" ixy="0.0" ixz="0.0"
               iyy="0.0001" iyz="0.0"
               izz="0.0001"/>
    </inertial>

    <collision>
      <origin xyz="0 0 0"/>
      <geometry>
        <cylinder radius="0.03" length="0.02"/>
      </geometry>
    </collision>

    <visual>
      <origin xyz="0 0 0"/>
      <geometry>
        <cylinder radius="0.03" length="0.02"/>
      </geometry>
      <material name="red">
        <color rgba="1 0 0 1"/>
      </material>
    </visual>
  </link>

  <joint name="wheel_right_joint" type="continuous">
    <parent link="base_link"/>
    <child link="wheel_right_link"/>
    <origin xyz="0 -0.075 0"/>
    <axis xyz="0 1 0"/>
  </joint>

  <!-- ================= IMU ================= -->
  <link name="imu_link">
    <inertial>
      <mass value="0.01"/>
      <origin xyz="0 0 0"/>
      <inertia ixx="1e-6" ixy="0.0" ixz="0.0"
               iyy="1e-6" iyz="0.0"
               izz="1e-6"/>
    </inertial>

    <visual>
      <origin xyz="0 0 0"/>
      <geometry>
        <sphere radius="0.02"/>
      </geometry>
      <material name="yellow">
        <color rgba="1 1 0 1"/>
      </material>
    </visual>
  </link>

  <joint name="imu_joint" type="fixed">
    <parent link="base_link"/>
    <child link="imu_link"/>
    <origin xyz="0 0 0.05"/>
  </joint>

  <!-- ================= FRICTION ================= -->
  <gazebo reference="wheel_left_link">
    <mu1>1.0</mu1>
    <mu2>1.0</mu2>
  </gazebo>

  <gazebo reference="wheel_right_link">
    <mu1>1.0</mu1>
    <mu2>1.0</mu2>
  </gazebo>

  <!-- ================= IMU SENSOR ================= -->
  <gazebo reference="imu_link">
  <sensor name="imu_sensor" type="imu">
    <always_on>true</always_on>
    <update_rate>50</update_rate>

    <imu>
      <orientation>
        <noise type="gaussian">
          <mean>0.0</mean>
          <stddev>0.0001</stddev>
        </noise>
      </orientation>

      <angular_velocity>
        <noise type="gaussian">
          <mean>0.0</mean>
          <stddev>0.0002</stddev>
        </noise>
      </angular_velocity>

      <linear_acceleration>
        <noise type="gaussian">
          <mean>0.0</mean>
          <stddev>0.0002</stddev>
        </noise>
      </linear_acceleration>
    </imu>

    <plugin name="imu_plugin" filename="libgazebo_ros_imu_sensor.so">
      <ros>
        <namespace>/</namespace>
        <remapping>~/out:=imu/data</remapping>
      </ros>
      <frame_name>imu_link</frame_name>
    </plugin>
  </sensor>
</gazebo>
  <!-- ================= DIFF DRIVE ================= -->
  <gazebo>
    <plugin name="diff_drive" filename="libgazebo_ros_diff_drive.so">

      <ros>
        <namespace>/</namespace>
      </ros>

      <left_joint>wheel_left_joint</left_joint>
      <right_joint>wheel_right_joint</right_joint>

      <wheel_separation>0.15</wheel_separation>
      <wheel_radius>0.03</wheel_radius>
      <wheel_diameter>0.06</wheel_diameter>
      <odom_topic>odom</odom_topic>
      <cmd_vel_topic>cmd_vel</cmd_vel_topic>

      <publish_odom>true</publish_odom>
      <publish_odom_tf>true</publish_odom_tf>

    </plugin>
  </gazebo>

</robot>